05/05/2020 14:31:56 - __main__ - DEBUG - parsing
05/05/2020 14:31:56 - pika.adapters.utils.io_services_utils - ERROR - Socket failed to connect: <socket.socket fd=7, family=AddressFamily.AF_INET, type=SocketKind.SOCK_STREAM, proto=6, laddr=('127.0.0.1', 43936)>; error=111 (Connection refused)
05/05/2020 14:31:56 - pika.adapters.utils.connection_workflow - ERROR - TCP Connection attempt failed: ConnectionRefusedError(111, 'Connection refused'); dest=(<AddressFamily.AF_INET: 2>, <SocketKind.SOCK_STREAM: 1>, 6, '', ('127.0.0.1', 5672))
05/05/2020 14:31:56 - pika.adapters.utils.connection_workflow - ERROR - AMQPConnector - reporting failure: AMQPConnectorSocketConnectError: ConnectionRefusedError(111, 'Connection refused')
05/05/2020 14:31:56 - pika.adapters.utils.connection_workflow - ERROR - AMQP connection workflow failed: AMQPConnectionWorkflowFailed: 1 exceptions in all; last exception - AMQPConnectorSocketConnectError: ConnectionRefusedError(111, 'Connection refused'); first exception - None.
05/05/2020 14:31:56 - pika.adapters.utils.connection_workflow - ERROR - AMQPConnectionWorkflow - reporting failure: AMQPConnectionWorkflowFailed: 1 exceptions in all; last exception - AMQPConnectorSocketConnectError: ConnectionRefusedError(111, 'Connection refused'); first exception - None
05/05/2020 14:31:56 - pika.adapters.blocking_connection - ERROR - Connection workflow failed: AMQPConnectionWorkflowFailed: 1 exceptions in all; last exception - AMQPConnectorSocketConnectError: ConnectionRefusedError(111, 'Connection refused'); first exception - None
05/05/2020 14:31:56 - pika.adapters.blocking_connection - ERROR - Error in _create_connection().
Traceback (most recent call last):
  File "/home/user/.pyenv/versions/3.8.0/lib/python3.8/site-packages/pika/adapters/blocking_connection.py", line 450, in _create_connection
    raise self._reap_last_connection_workflow_error(error)
pika.exceptions.AMQPConnectionError
05/05/2020 14:31:56 - pika.adapters.utils.io_services_utils - ERROR - Socket failed to connect: <socket.socket fd=4, family=AddressFamily.AF_INET, type=SocketKind.SOCK_STREAM, proto=6, laddr=('127.0.0.1', 43942)>; error=111 (Connection refused)
05/05/2020 14:31:56 - pika.adapters.utils.connection_workflow - ERROR - TCP Connection attempt failed: ConnectionRefusedError(111, 'Connection refused'); dest=(<AddressFamily.AF_INET: 2>, <SocketKind.SOCK_STREAM: 1>, 6, '', ('127.0.0.1', 5672))
05/05/2020 14:31:56 - pika.adapters.utils.connection_workflow - ERROR - AMQPConnector - reporting failure: AMQPConnectorSocketConnectError: ConnectionRefusedError(111, 'Connection refused')
05/05/2020 14:31:56 - pika.adapters.utils.connection_workflow - ERROR - AMQP connection workflow failed: AMQPConnectionWorkflowFailed: 1 exceptions in all; last exception - AMQPConnectorSocketConnectError: ConnectionRefusedError(111, 'Connection refused'); first exception - None.
05/05/2020 14:31:56 - pika.adapters.utils.connection_workflow - ERROR - AMQPConnectionWorkflow - reporting failure: AMQPConnectionWorkflowFailed: 1 exceptions in all; last exception - AMQPConnectorSocketConnectError: ConnectionRefusedError(111, 'Connection refused'); first exception - None
05/05/2020 14:31:56 - pika.adapters.blocking_connection - ERROR - Connection workflow failed: AMQPConnectionWorkflowFailed: 1 exceptions in all; last exception - AMQPConnectorSocketConnectError: ConnectionRefusedError(111, 'Connection refused'); first exception - None
05/05/2020 14:31:56 - pika.adapters.blocking_connection - ERROR - Error in _create_connection().
Traceback (most recent call last):
  File "/home/user/.pyenv/versions/3.8.0/lib/python3.8/site-packages/pika/adapters/blocking_connection.py", line 450, in _create_connection
    raise self._reap_last_connection_workflow_error(error)
pika.exceptions.AMQPConnectionError
05/05/2020 14:31:56 - pika.adapters.utils.io_services_utils - ERROR - Socket failed to connect: <socket.socket fd=4, family=AddressFamily.AF_INET, type=SocketKind.SOCK_STREAM, proto=6, laddr=('127.0.0.1', 43946)>; error=111 (Connection refused)
05/05/2020 14:31:56 - pika.adapters.utils.connection_workflow - ERROR - TCP Connection attempt failed: ConnectionRefusedError(111, 'Connection refused'); dest=(<AddressFamily.AF_INET: 2>, <SocketKind.SOCK_STREAM: 1>, 6, '', ('127.0.0.1', 5672))
05/05/2020 14:31:56 - pika.adapters.utils.connection_workflow - ERROR - AMQPConnector - reporting failure: AMQPConnectorSocketConnectError: ConnectionRefusedError(111, 'Connection refused')
05/05/2020 14:31:56 - pika.adapters.utils.connection_workflow - ERROR - AMQP connection workflow failed: AMQPConnectionWorkflowFailed: 1 exceptions in all; last exception - AMQPConnectorSocketConnectError: ConnectionRefusedError(111, 'Connection refused'); first exception - None.
05/05/2020 14:31:56 - pika.adapters.utils.connection_workflow - ERROR - AMQPConnectionWorkflow - reporting failure: AMQPConnectionWorkflowFailed: 1 exceptions in all; last exception - AMQPConnectorSocketConnectError: ConnectionRefusedError(111, 'Connection refused'); first exception - None
05/05/2020 14:31:56 - pika.adapters.blocking_connection - ERROR - Connection workflow failed: AMQPConnectionWorkflowFailed: 1 exceptions in all; last exception - AMQPConnectorSocketConnectError: ConnectionRefusedError(111, 'Connection refused'); first exception - None
05/05/2020 14:31:56 - pika.adapters.blocking_connection - ERROR - Error in _create_connection().
Traceback (most recent call last):
  File "/home/user/.pyenv/versions/3.8.0/lib/python3.8/site-packages/pika/adapters/blocking_connection.py", line 450, in _create_connection
    raise self._reap_last_connection_workflow_error(error)
pika.exceptions.AMQPConnectionError
05/05/2020 14:31:56 - pika.adapters.utils.io_services_utils - ERROR - Socket failed to connect: <socket.socket fd=4, family=AddressFamily.AF_INET, type=SocketKind.SOCK_STREAM, proto=6, laddr=('127.0.0.1', 43948)>; error=111 (Connection refused)
05/05/2020 14:31:56 - pika.adapters.utils.connection_workflow - ERROR - TCP Connection attempt failed: ConnectionRefusedError(111, 'Connection refused'); dest=(<AddressFamily.AF_INET: 2>, <SocketKind.SOCK_STREAM: 1>, 6, '', ('127.0.0.1', 5672))
05/05/2020 14:31:56 - pika.adapters.utils.connection_workflow - ERROR - AMQPConnector - reporting failure: AMQPConnectorSocketConnectError: ConnectionRefusedError(111, 'Connection refused')
05/05/2020 14:31:56 - pika.adapters.utils.connection_workflow - ERROR - AMQP connection workflow failed: AMQPConnectionWorkflowFailed: 1 exceptions in all; last exception - AMQPConnectorSocketConnectError: ConnectionRefusedError(111, 'Connection refused'); first exception - None.
05/05/2020 14:31:56 - pika.adapters.utils.connection_workflow - ERROR - AMQPConnectionWorkflow - reporting failure: AMQPConnectionWorkflowFailed: 1 exceptions in all; last exception - AMQPConnectorSocketConnectError: ConnectionRefusedError(111, 'Connection refused'); first exception - None
05/05/2020 14:31:56 - pika.adapters.blocking_connection - ERROR - Connection workflow failed: AMQPConnectionWorkflowFailed: 1 exceptions in all; last exception - AMQPConnectorSocketConnectError: ConnectionRefusedError(111, 'Connection refused'); first exception - None
05/05/2020 14:31:56 - pika.adapters.blocking_connection - ERROR - Error in _create_connection().
Traceback (most recent call last):
  File "/home/user/.pyenv/versions/3.8.0/lib/python3.8/site-packages/pika/adapters/blocking_connection.py", line 450, in _create_connection
    raise self._reap_last_connection_workflow_error(error)
pika.exceptions.AMQPConnectionError
